Workbook
Name College: #REF!
Name College: #REF!
Name College: #REF!
Name College: #REF!
Name College: #REF!
Name College: #REF!
Name College: #REF!
Name College: #REF!
Name College: #REF!
Name College: #REF!
Name d: #REF!
Name d: #REF!
Name d: #REF!
Name d: #REF!
Name d: #REF!
Name d: #REF!
Name d: #REF!
Name d: #REF!
Name d: #REF!
Name JR_PAGE_ANCHOR_0_1: #REF!
Name JR_PAGE_ANCHOR_0_1: #REF!

Sheet 1UniNo
B1: Table | C1: 1. State & Type-wise Number of Universities
A2: Sl. No. | B2: State/UTs | C2: Central University | D2: Central Open University | E2: Institute of National Importance | F2: State Public University | G2: Institute under State Legislature Act | H2: State Open University | I2: State Private University | J2: State Private Open University | K2: Deemed University-Government | L2: Deemed University-Government Aided | M2: Deemed University-Private | N2: Grand Total
A3: 1 | B3: 2 | C3: 3 | D3: 4 | E3: 5 | F3: 6 | G3: 7 | H3: 8 | I3: 9 | J3: 10 | K3: 11 | L3: 12 | M3: 13 | N3: 14
A4: 1 | B4: Andhra Pradesh | C4: 1 | E4: 9 | F4: 22 | G4: 1 | I4: 3 | K4: 1 | M4: 4 | N4: =SUM(C4:M4) -> 41
A5: 2 | B5: Arunachal Pradesh | C5: 1 | E5: 1 | I5: 6 | J5: 1 | K5: 1 | N5: =SUM(C5:M5) -> 10
A6: 3 | B6: Assam | C6: 2 | E6: 4 | F6: 12 | H6: 1 | I6: 6 | K6: 1 | N6: =SUM(C6:M6) -> 26
A7: 4 | B7: Bihar | C7: 4 | E7: 5 | F7: 17 | G7: 1 | H7: 1 | I7: 6 | K7: 1 | N7: =SUM(C7:M7) -> 35
A8: 5 | B8: Chandigarh | E8: 1 | F8: 1 | K8: 1 | N8: =SUM(C8:M8) -> 3
A9: 6 | B9: Chhattisgarh | C9: 1 | E9: 4 | F9: 13 | H9: 1 | I9: 9 | N9: =SUM(C9:M9) -> 28
A10: 7 | B10: Delhi | C10: 5 | D10: 1 | E10: 5 | F10: 8 | K10: 7 | L10: 1 | M10: 1 | N10: =SUM(C10:M10) -> 28
A11: 8 | B11: Goa | E11: 2 | F11: 1 | N11: =SUM(C11:M11) -> 3
A12: 9 | B12: Gujarat | C12: 1 | E12: 6 | F12: 28 | H12: 1 | I12: 37 | K12: 1 | L12: 1 | M12: 1 | N12: =SUM(C12:M12) -> 76
A13: 10 | B13: Haryana | C13: 1 | E13: 5 | F13: 18 | I13: 23 | K13: 3 | M13: 3 | N13: =SUM(C13:M13) -> 53
A14: 11 | B14: Himachal Pradesh | C14: 1 | E14: 4 | F14: 5 | I14: 17 | N14: =SUM(C14:M14) -> 27
A15: 12 | B15: Jammu and Kashmir | C15: 2 | E15: 3 | F15: 9 | G15: 1 | N15: =SUM(C15:M15) -> 15
A16: 13 | B16: Jharkhand | C16: 1 | E16: 5 | F16: 11 | I16: 14 | M16: 1 | N16: =SUM(C16:M16) -> 32
A17: 14 | B17: Karnataka | C17: 1 | E17: 4 | F17: 30 | H17: 1 | I17: 18 | K17: 4 | M17: 11 | N17: =SUM(C17:M17) -> 69
A18: 15 | B18: Kerala | C18: 1 | E18: 6 | F18: 13 | K18: 2 | M18: 1 | N18: =SUM(C18:M18) -> 23
A19: 16 | B19: Ladakh | K19: 1 | N19: =SUM(C19:M19) -> 1
A20: 17 | B20: Madhya Pradesh | C20: 2 | E20: 8 | F20: 21 | H20: 1 | I20: 33 | K20: 1 | N20: =SUM(C20:M20) -> 66
A21: 18 | B21: Maharashtra | C21: 1 | E21: 8 | F21: 23 | H21: 1 | I21: 11 | K21: 7 | L21: 2 | M21: 12 | N21: =SUM(C21:M21) -> 65
A22: 19 | B22: Manipur | C22: 3 | E22: 2 | F22: 3 | N22: =SUM(C22:M22) -> 8
A23: 20 | B23: Meghalaya | C23: 1 | E23: 2 | I23: 7 | N23: =SUM(C23:M23) -> 10
A24: 21 | B24: Mizoram | C24: 1 | E24: 1 | I24: 1 | N24: =SUM(C24:M24) -> 3
A25: 22 | B25: Nagaland | C25: 1 | E25: 1 | I25: 3 | N25: =SUM(C25:M25) -> 5
A26: 23 | B26: Odisha | C26: 1 | E26: 5 | F26: 16 | H26: 1 | I26: 6 | M26: 3 | N26: =SUM(C26:M26) -> 32
A27: 24 | B27: Puducherry | C27: 1 | E27: 2 | M27: 1 | N27: =SUM(C27:M27) -> 4
A28: 25 | B28: Punjab | C28: 1 | E28: 5 | F28: 9 | I28: 15 | K28: 1 | M28: 1 | N28: =SUM(C28:M28) -> 32
A29: 26 | B29: Rajasthan | C29: 1 | E29: 5 | F29: 25 | H29: 1 | I29: 50 | M29: 7 | N29: =SUM(C29:M29) -> 89
A30: 27 | B30: Sikkim | C30: 1 | E30: 1 | F30: 1 | I30: 5 | N30: =SUM(C30:M30) -> 8
A31: 28 | B31: Tamil Nadu | C31: 2 | E31: 7 | F31: 21 | H31: 1 | L31: 2 | M31: 26 | N31: =SUM(C31:M31) -> 59
A32: 29 | B32: Telangana | C32: 3 | E32: 2 | F32: 15 | G32: 1 | H32: 1 | M32: 2 | N32: =SUM(C32:M32) -> 24
A33: 30 | B33: Tripura | C33: 1 | E33: 1 | F33: 1 | I33: 1 | N33: =SUM(C33:M33) -> 4
A34: 31 | B34: Uttar Pradesh | C34: 4 | E34: 9 | F34: 28 | G34: 1 | H34: 1 | I34: 29 | K34: 2 | L34: 3 | M34: 4 | N34: =SUM(C34:M34) -> 81
A35: 32 | B35: Uttarakhand | C35: 1 | E35: 4 | F35: 10 | H35: 1 | I35: 17 | K35: 1 | L35: 1 | M35: 1 | N35: =SUM(C35:M35) -> 36
A36: 33 | B36: West Bengal | C36: 1 | E36: 8 | F36: 25 | H36: 1 | I36: 10 | K36: 1 | M36: 1 | N36: =SUM(C36:M36) -> 47
A37: All India | C37: =SUM(C4:C36) -> 48 | D37: =SUM(D4:D36) -> 1 | E37: =SUM(E4:E36) -> 135 | F37: =SUM(F4:F36) -> 386 | G37: =SUM(G4:G36) -> 5 | H37: =SUM(H4:H36) -> 14 | I37: =SUM(I4:I36) -> 327 | J37: =SUM(J4:J36) -> 1 | ... N37: =SUM(N4:N36) -> 1043
A38: In UTs of Andaman & Nicobar Islands, Dadra & Nagar Haveli, Daman & Diu and Lakshadweep, there is no University.

Sheet 1InsResponse
B1: Table 1a. | C1: Total Number of Institutions Registered and Responded in AISHE 2019-20
A2: Sl. No. | B2: State/UTs | C2: Unversities | F2: Colleges | I2: Stand Alone Institutions | L2: Total
C3: Registered | D3: Responded | E3: % of Response | F3: Registered | G3: Responded | H3: % of Response | I3: Registered | J3: Responded | K3: % of Response | L3: Registered | M3: Responded | N3: % of Response
A4: 1 | B4: 2 | C4: 3 | D4: 4 | E4: 5 | F4: 6 | G4: 7 | H4: 8 | I4: 9 | J4: 10 | K4: 11 | L4: 12 | M4: 13 | N4: 14
A5: 1 | B5: Andaman and Nicobar Islands | C5: =SUMIF('1UniNo'!B:B,B5,'1UniNo'!N:N) -> 0 | D5: =SUMIF('2University-Specialisation'!B:B,B5,'2University-Specialisation'!W:W) -> 0 | E5: 0 | F5: =SUMIF('8CollegeAct'!B:B,B5,'8CollegeAct'!C:C) -> 8 | G5: =SUMIF('5ManagementCollegeNo'!B:B,B5,'5ManagementCollegeNo'!G:G) -> 8 | H5: =G5/F5% -> 100 | I5: =SUMIF('9AllSAAct'!$B:$B,$B5,'9AllSAAct'!AS:AS) -> 1 | J5: =SUMIF('9AllSAAct'!$B:$B,$B5,'9AllSAAct'!AT:AT) -> 1 | K5: =J5/I5% -> 100 | L5: =C5+F5+I5 -> 9 | M5: =D5+G5+J5 -> 9 | N5: =M5/L5% -> 100
A6: 2 | B6: Andhra Pradesh | C6: =SUMIF('1UniNo'!B:B,B6,'1UniNo'!N:N) -> 41 | D6: =SUMIF('2University-Specialisation'!B:B,B6,'2University-Specialisation'!W:W) -> 39 | E6: =D6/C6% -> 95.121951 | F6: =SUMIF('8CollegeAct'!B:B,B6,'8CollegeAct'!C:C) -> 2750 | G6: =SUMIF('5ManagementCollegeNo'!B:B,B6,'5ManagementCollegeNo'!G:G) -> 2501 | H6: =G6/F6% -> 90.945455 | I6: =SUMIF('9AllSAAct'!$B:$B,$B6,'9AllSAAct'!AS:AS) -> 843 | J6: =SUMIF('9AllSAAct'!$B:$B,$B6,'9AllSAAct'!AT:AT) -> 646 | K6: =J6/I6% -> 76.631079 | L6: =C6+F6+I6 -> 3634 | M6: =D6+G6+J6 -> 3186 | N6: =M6/L6% -> 87.671987
A7: 3 | B7: Arunachal Pradesh | C7: =SUMIF('1UniNo'!B:B,B7,'1UniNo'!N:N) -> 10 | D7: =SUMIF('2University-Specialisation'!B:B,B7,'2University-Specialisation'!W:W) -> 10 | E7: =D7/C7% -> 100 | F7: =SUMIF('8CollegeAct'!B:B,B7,'8CollegeAct'!C:C) -> 39 | G7: =SUMIF('5ManagementCollegeNo'!B:B,B7,'5ManagementCollegeNo'!G:G) -> 38 | H7: =G7/F7% -> 97.435897 | I7: =SUMIF('9AllSAAct'!$B:$B,$B7,'9AllSAAct'!AS:AS) -> 13 | J7: =SUMIF('9AllSAAct'!$B:$B,$B7,'9AllSAAct'!AT:AT) -> 6 | K7: =J7/I7% -> 46.153846 | L7: =C7+F7+I7 -> 62 | M7: =D7+G7+J7 -> 54 | N7: =M7/L7% -> 87.096774
A8: 4 | B8: Assam | C8: =SUMIF('1UniNo'!B:B,B8,'1UniNo'!N:N) -> 26 | D8: =SUMIF('2University-Specialisation'!B:B,B8,'2University-Specialisation'!W:W) -> 26 | E8: =D8/C8% -> 100 | F8: =SUMIF('8CollegeAct'!B:B,B8,'8CollegeAct'!C:C) -> 558 | G8: =SUMIF('5ManagementCollegeNo'!B:B,B8,'5ManagementCollegeNo'!G:G) -> 533 | H8: =G8/F8% -> 95.519713 | I8: =SUMIF('9AllSAAct'!$B:$B,$B8,'9AllSAAct'!AS:AS) -> 92 | J8: =SUMIF('9AllSAAct'!$B:$B,$B8,'9AllSAAct'!AT:AT) -> 74 | K8: =J8/I8% -> 80.434783 | L8: =C8+F8+I8 -> 676 | M8: =D8+G8+J8 -> 633 | N8: =M8/L8% -> 93.639053
A9: 5 | B9: Bihar | C9: =SUMIF('1UniNo'!B:B,B9,'1UniNo'!N:N) -> 35 | D9: =SUMIF('2University-Specialisation'!B:B,B9,'2University-Specialisation'!W:W) -> 35 | E9: =D9/C9% -> 100 | F9: =SUMIF('8CollegeAct'!B:B,B9,'8CollegeAct'!C:C) -> 874 | G9: =SUMIF('5ManagementCollegeNo'!B:B,B9,'5ManagementCollegeNo'!G:G) -> 863 | H9: =G9/F9% -> 98.741419 | I9: =SUMIF('9AllSAAct'!$B:$B,$B9,'9AllSAAct'!AS:AS) -> 166 | J9: =SUMIF('9AllSAAct'!$B:$B,$B9,'9AllSAAct'!AT:AT) -> 158 | K9: =J9/I9% -> 95.180723 | L9: =C9+F9+I9 -> 1075 | M9: =D9+G9+J9 -> 1056 | N9: =M9/L9% -> 98.232558
A10: 6 | B10: Chandigarh | C10: =SUMIF('1UniNo'!B:B,B10,'1UniNo'!N:N) -> 3 | D10: =SUMIF('2University-Specialisation'!B:B,B10,'2University-Specialisation'!W:W) -> 3 | E10: =D10/C10% -> 100 | F10: =SUMIF('8CollegeAct'!B:B,B10,'8CollegeAct'!C:C) -> 25 | G10: =SUMIF('5ManagementCollegeNo'!B:B,B10,'5ManagementCollegeNo'!G:G) -> 25 | H10: =G10/F10% -> 100 | I10: =SUMIF('9AllSAAct'!$B:$B,$B10,'9AllSAAct'!AS:AS) -> 10 | J10: =SUMIF('9AllSAAct'!$B:$B,$B10,'9AllSAAct'!AT:AT) -> 9 | K10: =J10/I10% -> 90 | L10: =C10+F10+I10 -> 38 | M10: =D10+G10+J10 -> 37 | N10: =M10/L10% -> 97.368421
A11: 7 | B11: Chhattisgarh | C11: =SUMIF('1UniNo'!B:B,B11,'1UniNo'!N:N) -> 28 | D11: =SUMIF('2University-Specialisation'!B:B,B11,'2University-Specialisation'!W:W) -> 28 | E11: =D11/C11% -> 100 | F11: =SUMIF('8CollegeAct'!B:B,B11,'8CollegeAct'!C:C) -> 810 | G11: =SUMIF('5ManagementCollegeNo'!B:B,B11,'5ManagementCollegeNo'!G:G) -> 807 | H11: =G11/F11% -> 99.62963 | I11: =SUMIF('9AllSAAct'!$B:$B,$B11,'9AllSAAct'!AS:AS) -> 75 | J11: =SUMIF('9AllSAAct'!$B:$B,$B11,'9AllSAAct'!AT:AT) -> 70 | K11: =J11/I11% -> 93.333333 | L11: =C11+F11+I11 -> 913 | M11: =D11+G11+J11 -> 905 | N11: =M11/L11% -> 99.123768
A12: 8 | B12: Dadra and Nagar Haveli | C12: =SUMIF('1UniNo'!B:B,B12,'1UniNo'!N:N) -> 0 | D12: =SUMIF('2University-Specialisation'!B:B,B12,'2University-Specialisation'!W:W) -> 0 | F12: =SUMIF('8CollegeAct'!B:B,B12,'8CollegeAct'!C:C) -> 8 | G12: =SUMIF('5ManagementCollegeNo'!B:B,B12,'5ManagementCollegeNo'!G:G) -> 8 | H12: =G12/F12% -> 100 | I12: =SUMIF('9AllSAAct'!$B:$B,$B12,'9AllSAAct'!AS:AS) -> 2 | J12: =SUMIF('9AllSAAct'!$B:$B,$B12,'9AllSAAct'!AT:AT) -> 1 | K12: =J12/I12% -> 50 | L12: =C12+F12+I12 -> 10 | M12: =D12+G12+J12 -> 9 | N12: =M12/L12% -> 90
A13: 9 | B13: Daman and Diu | C13: =SUMIF('1UniNo'!B:B,B13,'1UniNo'!N:N) -> 0 | D13: =SUMIF('2University-Specialisation'!B:B,B13,'2University-Specialisation'!W:W) -> 0 | F13: =SUMIF('8CollegeAct'!B:B,B13,'8CollegeAct'!C:C) -> 10 | G13: =SUMIF('5ManagementCollegeNo'!B:B,B13,'5ManagementCollegeNo'!G:G) -> 10 | H13: =G13/F13% -> 100 | I13: =SUMIF('9AllSAAct'!$B:$B,$B13,'9AllSAAct'!AS:AS) -> 2 | J13: =SUMIF('9AllSAAct'!$B:$B,$B13,'9AllSAAct'!AT:AT) -> 0 | K13: =J13/I13% -> 0 | L13: =C13+F13+I13 -> 12 | M13: =D13+G13+J13 -> 10 | N13: =M13/L13% -> 83.333333
A14: 10 | B14: Delhi | C14: =SUMIF('1UniNo'!B:B,B14,'1UniNo'!N:N) -> 28 | D14: =SUMIF('2University-Specialisation'!B:B,B14,'2University-Specialisation'!W:W) -> 27 | E14: =D14/C14% -> 96.428571 | F14: =SUMIF('8CollegeAct'!B:B,B14,'8CollegeAct'!C:C) -> 179 | G14: =SUMIF('5ManagementCollegeNo'!B:B,B14,'5ManagementCollegeNo'!G:G) -> 174 | H14: =G14/F14% -> 97.206704 | I14: =SUMIF('9AllSAAct'!$B:$B,$B14,'9AllSAAct'!AS:AS) -> 112 | J14: =SUMIF('9AllSAAct'!$B:$B,$B14,'9AllSAAct'!AT:AT) -> 83 | K14: =J14/I14% -> 74.107143 | L14: =C14+F14+I14 -> 319 | M14: =D14+G14+J14 -> 284 | N14: =M14/L14% -> 89.028213
A15: 11 | B15: Goa | C15: =SUMIF('1UniNo'!B:B,B15,'1UniNo'!N:N) -> 3 | D15: =SUMIF('2University-Specialisation'!B:B,B15,'2University-Specialisation'!W:W) -> 3 | E15: =D15/C15% -> 100 | F15: =SUMIF('8CollegeAct'!B:B,B15,'8CollegeAct'!C:C) -> 58 | G15: =SUMIF('5ManagementCollegeNo'!B:B,B15,'5ManagementCollegeNo'!G:G) -> 58 | H15: =G15/F15% -> 100 | I15: =SUMIF('9AllSAAct'!$B:$B,$B15,'9AllSAAct'!AS:AS) -> 12 | J15: =SUMIF('9AllSAAct'!$B:$B,$B15,'9AllSAAct'!AT:AT) -> 11 | K15: =J15/I15% -> 91.666667 | L15: =C15+F15+I15 -> 73 | M15: =D15+G15+J15 -> 72 | N15: =M15/L15% -> 98.630137
A16: 12 | B16: Gujarat | C16: =SUMIF('1UniNo'!B:B,B16,'1UniNo'!N:N) -> 76 | D16: =SUMIF('2University-Specialisation'!B:B,B16,'2University-Specialisation'!W:W) -> 76 | E16: =D16/C16% -> 100 | F16: =SUMIF('8CollegeAct'!B:B,B16,'8CollegeAct'!C:C) -> 2275 | G16: =SUMIF('5ManagementCollegeNo'!B:B,B16,'5ManagementCollegeNo'!G:G) -> 2258 | H16: =G16/F16% -> 99.252747 | I16: =SUMIF('9AllSAAct'!$B:$B,$B16,'9AllSAAct'!AS:AS) -> 308 | J16: =SUMIF('9AllSAAct'!$B:$B,$B16,'9AllSAAct'!AT:AT) -> 307 | K16: =J16/I16% -> 99.675325 | L16: =C16+F16+I16 -> 2659 | M16: =D16+G16+J16 -> 2641 | N16: =M16/L16% -> 99.323054
A17: 13 | B17: Haryana | C17: =SUMIF('1UniNo'!B:B,B17,'1UniNo'!N:N) -> 53 | D17: =SUMIF('2University-Specialisation'!B:B,B17,'2University-Specialisation'!W:W) -> 51 | E17: =D17/C17% -> 96.226415 | F17: =SUMIF('8CollegeAct'!B:B,B17,'8CollegeAct'!C:C) -> 1087 | G17: =SUMIF('5ManagementCollegeNo'!B:B,B17,'5ManagementCollegeNo'!G:G) -> 1034 | H17: =G17/F17% -> 95.124195 | I17: =SUMIF('9AllSAAct'!$B:$B,$B17,'9AllSAAct'!AS:AS) -> 252 | J17: =SUMIF('9AllSAAct'!$B:$B,$B17,'9AllSAAct'!AT:AT) -> 190 | K17: =J17/I17% -> 75.396825 | L17: =C17+F17+I17 -> 1392 | M17: =D17+G17+J17 -> 1275 | N17: =M17/L17% -> 91.594828
A18: 14 | B18: Himachal Pradesh | C18: =SUMIF('1UniNo'!B:B,B18,'1UniNo'!N:N) -> 27 | D18: =SUMIF('2University-Specialisation'!B:B,B18,'2University-Specialisation'!W:W) -> 27 | E18: =D18/C18% -> 100 | F18: =SUMIF('8CollegeAct'!B:B,B18,'8CollegeAct'!C:C) -> 344 | G18: =SUMIF('5ManagementCollegeNo'!B:B,B18,'5ManagementCollegeNo'!G:G) -> 344 | H18: =G18/F18% -> 100 | I18: =SUMIF('9AllSAAct'!$B:$B,$B18,'9AllSAAct'!AS:AS) -> 83 | J18: =SUMIF('9AllSAAct'!$B:$B,$B18,'9AllSAAct'!AT:AT) -> 81 | K18: =J18/I18% -> 97.590361 | L18: =C18+F18+I18 -> 454 | M18: =D18+G18+J18 -> 452 | N18: =M18/L18% -> 99.559471
A19: 15 | B19: Jammu and Kashmir | C19: =SUMIF('1UniNo'!B:B,B19,'1UniNo'!N:N) -> 15 | D19: =SUMIF('2University-Specialisation'!B:B,B19,'2University-Specialisation'!W:W) -> 15 | E19: =D19/C19% -> 100 | F19: =SUMIF('8CollegeAct'!B:B,B19,'8CollegeAct'!C:C) -> 316 | G19: =SUMIF('5ManagementCollegeNo'!B:B,B19,'5ManagementCollegeNo'!G:G) -> 313 | H19: =G19/F19% -> 99.050633 | I19: =SUMIF('9AllSAAct'!$B:$B,$B19,'9AllSAAct'!AS:AS) -> 118 | J19: =SUMIF('9AllSAAct'!$B:$B,$B19,'9AllSAAct'!AT:AT) -> 99 | K19: =J19/I19% -> 83.898305 | L19: =C19+F19+I19 -> 449 | M19: =D19+G19+J19 -> 427 | N19: =M19/L19% -> 95.100223
A20: 16 | B20: Jharkhand | C20: =SUMIF('1UniNo'!B:B,B20,'1UniNo'!N:N) -> 32 | D20: =SUMIF('2University-Specialisation'!B:B,B20,'2University-Specialisation'!W:W) -> 31 | E20: =D20/C20% -> 96.875 | F20: =SUMIF('8CollegeAct'!B:B,B20,'8CollegeAct'!C:C) -> 323 | G20: =SUMIF('5ManagementCollegeNo'!B:B,B20,'5ManagementCollegeNo'!G:G) -> 317 | H20: =G20/F20% -> 98.142415 | I20: =SUMIF('9AllSAAct'!$B:$B,$B20,'9AllSAAct'!AS:AS) -> 91 | J20: =SUMIF('9AllSAAct'!$B:$B,$B20,'9AllSAAct'!AT:AT) -> 83 | K20: =J20/I20% -> 91.208791 | L20: =C20+F20+I20 -> 446 | M20: =D20+G20+J20 -> 431 | N20: =M20/L20% -> 96.636771
A21: 17 | B21: Karnataka | C21: =SUMIF('1UniNo'!B:B,B21,'1UniNo'!N:N) -> 69 | D21: =SUMIF('2University-Specialisation'!B:B,B21,'2University-Specialisation'!W:W) -> 69 | E21: =D21/C21% -> 100 | F21: =SUMIF('8CollegeAct'!B:B,B21,'8CollegeAct'!C:C) -> 4047 | G21: =SUMIF('5ManagementCollegeNo'!B:B,B21,'5ManagementCollegeNo'!G:G) -> 3971 | H21: =G21/F21% -> 98.122066 | I21: =SUMIF('9AllSAAct'!$B:$B,$B21,'9AllSAAct'!AS:AS) -> 1690 | J21: =SUMIF('9AllSAAct'!$B:$B,$B21,'9AllSAAct'!AT:AT) -> 1098 | K21: =J21/I21% -> 64.970414 | L21: =C21+F21+I21 -> 5806 | M21: =D21+G21+J21 -> 5138 | N21: =M21/L21% -> 88.494661
A22: 18 | B22: Kerala | C22: =SUMIF('1UniNo'!B:B,B22,'1UniNo'!N:N) -> 23 | D22: =SUMIF('2University-Specialisation'!B:B,B22,'2University-Specialisation'!W:W) -> 23 | E22: =D22/C22% -> 100 | F22: =SUMIF('8CollegeAct'!B:B,B22,'8CollegeAct'!C:C) -> 1417 | G22: =SUMIF('5ManagementCollegeNo'!B:B,B22,'5ManagementCollegeNo'!G:G) -> 1313 | H22: =G22/F22% -> 92.66055 | I22: =SUMIF('9AllSAAct'!$B:$B,$B22,'9AllSAAct'!AS:AS) -> 452 | J22: =SUMIF('9AllSAAct'!$B:$B,$B22,'9AllSAAct'!AT:AT) -> 359 | K22: =J22/I22% -> 79.424779 | L22: =C22+F22+I22 -> 1892 | M22: =D22+G22+J22 -> 1695 | N22: =M22/L22% -> 89.587738
A23: 19 | B23: Ladakh | C23: =SUMIF('1UniNo'!B:B,B23,'1UniNo'!N:N) -> 1 | D23: =SUMIF('2University-Specialisation'!B:B,B23,'2University-Specialisation'!W:W) -> 1 | E23: =D23/C23% -> 100 | F23: =SUMIF('8CollegeAct'!B:B,B23,'8CollegeAct'!C:C) -> 5 | G23: =SUMIF('5ManagementCollegeNo'!B:B,B23,'5ManagementCollegeNo'!G:G) -> 5 | H23: =G23/F23% -> 100 | I23: =SUMIF('9AllSAAct'!$B:$B,$B23,'9AllSAAct'!AS:AS) -> 4 | J23: =SUMIF('9AllSAAct'!$B:$B,$B23,'9AllSAAct'!AT:AT) -> 4 | K23: =J23/I23% -> 100 | L23: =C23+F23+I23 -> 10 | M23: =D23+G23+J23 -> 10 | N23: =M23/L23% -> 100
A24: 20 | B24: Lakshadweep* | I24: =SUMIF('9AllSAAct'!$B:$B,$B24,'9AllSAAct'!AS:AS) -> 0 | J24: =SUMIF('9AllSAAct'!$B:$B,$B24,'9AllSAAct'!AT:AT) -> 0
A25: 21 | B25: Madhya Pradesh | C25: =SUMIF('1UniNo'!B:B,B25,'1UniNo'!N:N) -> 66 | D25: =SUMIF('2University-Specialisation'!B:B,B25,'2University-Specialisation'!W:W) -> 59 | E25: =D25/C25% -> 89.393939 | F25: =SUMIF('8CollegeAct'!B:B,B25,'8CollegeAct'!C:C) -> 2411 | G25: =SUMIF('5ManagementCollegeNo'!B:B,B25,'5ManagementCollegeNo'!G:G) -> 1946 | H25: =G25/F25% -> 80.713397 | I25: =SUMIF('9AllSAAct'!$B:$B,$B25,'9AllSAAct'!AS:AS) -> 379 | J25: =SUMIF('9AllSAAct'!$B:$B,$B25,'9AllSAAct'!AT:AT) -> 167 | K25: =J25/I25% -> 44.063325 | L25: =C25+F25+I25 -> 2856 | M25: =D25+G25+J25 -> 2172 | N25: =M25/L25% -> 76.05042
A26: 22 | B26: Maharashtra | C26: =SUMIF('1UniNo'!B:B,B26,'1UniNo'!N:N) -> 65 | D26: =SUMIF('2University-Specialisation'!B:B,B26,'2University-Specialisation'!W:W) -> 65 | E26: =D26/C26% -> 100 | F26: =SUMIF('8CollegeAct'!B:B,B26,'8CollegeAct'!C:C) -> 4494 | G26: =SUMIF('5ManagementCollegeNo'!B:B,B26,'5ManagementCollegeNo'!G:G) -> 4494 | H26: =G26/F26% -> 100 | I26: =SUMIF('9AllSAAct'!$B:$B,$B26,'9AllSAAct'!AS:AS) -> 2393 | J26: =SUMIF('9AllSAAct'!$B:$B,$B26,'9AllSAAct'!AT:AT) -> 2110 | K26: =J26/I26% -> 88.17384 | L26: =C26+F26+I26 -> 6952 | M26: =D26+G26+J26 -> 6669 | N26: =M26/L26% -> 95.929229
A27: 23 | B27: Manipur | C27: =SUMIF('1UniNo'!B:B,B27,'1UniNo'!N:N) -> 8 | D27: =SUMIF('2University-Specialisation'!B:B,B27,'2University-Specialisation'!W:W) -> 7 | E27: =D27/C27% -> 87.5 | F27: =SUMIF('8CollegeAct'!B:B,B27,'8CollegeAct'!C:C) -> 102 | G27: =SUMIF('5ManagementCollegeNo'!B:B,B27,'5ManagementCollegeNo'!G:G) -> 101 | H27: =G27/F27% -> 99.019608 | I27: =SUMIF('9AllSAAct'!$B:$B,$B27,'9AllSAAct'!AS:AS) -> 29 | J27: =SUMIF('9AllSAAct'!$B:$B,$B27,'9AllSAAct'!AT:AT) -> 28 | K27: =J27/I27% -> 96.551724 | L27: =C27+F27+I27 -> 139 | M27: =D27+G27+J27 -> 136 | N27: =M27/L27% -> 97.841727
A28: 24 | B28: Meghalaya | C28: =SUMIF('1UniNo'!B:B,B28,'1UniNo'!N:N) -> 10 | D28: =SUMIF('2University-Specialisation'!B:B,B28,'2University-Specialisation'!W:W) -> 9 | E28: =D28/C28% -> 90 | F28: =SUMIF('8CollegeAct'!B:B,B28,'8CollegeAct'!C:C) -> 67 | G28: =SUMIF('5ManagementCollegeNo'!B:B,B28,'5ManagementCollegeNo'!G:G) -> 57 | H28: =G28/F28% -> 85.074627 | I28: =SUMIF('9AllSAAct'!$B:$B,$B28,'9AllSAAct'!AS:AS) -> 21 | J28: =SUMIF('9AllSAAct'!$B:$B,$B28,'9AllSAAct'!AT:AT) -> 19 | K28: =J28/I28% -> 90.47619 | L28: =C28+F28+I28 -> 98 | M28: =D28+G28+J28 -> 85 | N28: =M28/L28% -> 86.734694
A29: 25 | B29: Mizoram | C29: =SUMIF('1UniNo'!B:B,B29,'1UniNo'!N:N) -> 3 | D29: =SUMIF('2University-Specialisation'!B:B,B29,'2University-Specialisation'!W:W) -> 3 | E29: =D29/C29% -> 100 | F29: =SUMIF('8CollegeAct'!B:B,B29,'8CollegeAct'!C:C) -> 35 | G29: =SUMIF('5ManagementCollegeNo'!B:B,B29,'5ManagementCollegeNo'!G:G) -> 35 | H29: =G29/F29% -> 100 | I29: =SUMIF('9AllSAAct'!$B:$B,$B29,'9AllSAAct'!AS:AS) -> 16 | J29: =SUMIF('9AllSAAct'!$B:$B,$B29,'9AllSAAct'!AT:AT) -> 16 | K29: =J29/I29% -> 100 | L29: =C29+F29+I29 -> 54 | M29: =D29+G29+J29 -> 54 | N29: =M29/L29% -> 100
A30: 26 | B30: Nagaland | C30: =SUMIF('1UniNo'!B:B,B30,'1UniNo'!N:N) -> 5 | D30: =SUMIF('2University-Specialisation'!B:B,B30,'2University-Specialisation'!W:W) -> 5 | E30: =D30/C30% -> 100 | F30: =SUMIF('8CollegeAct'!B:B,B30,'8CollegeAct'!C:C) -> 67 | G30: =SUMIF('5ManagementCollegeNo'!B:B,B30,'5ManagementCollegeNo'!G:G) -> 66 | H30: =G30/F30% -> 98.507463 | I30: =SUMIF('9AllSAAct'!$B:$B,$B30,'9AllSAAct'!AS:AS) -> 20 | J30: =SUMIF('9AllSAAct'!$B:$B,$B30,'9AllSAAct'!AT:AT) -> 17 | K30: =J30/I30% -> 85 | L30: =C30+F30+I30 -> 92 | M30: =D30+G30+J30 -> 88 | N30: =M30/L30% -> 95.652174
A31: 27 | B31: Odisha | C31: =SUMIF('1UniNo'!B:B,B31,'1UniNo'!N:N) -> 32 | D31: =SUMIF('2University-Specialisation'!B:B,B31,'2University-Specialisation'!W:W) -> 32 | E31: =D31/C31% -> 100 | F31: =SUMIF('8CollegeAct'!B:B,B31,'8CollegeAct'!C:C) -> 1087 | G31: =SUMIF('5ManagementCollegeNo'!B:B,B31,'5ManagementCollegeNo'!G:G) -> 1077 | H31: =G31/F31% -> 99.080037 | I31: =SUMIF('9AllSAAct'!$B:$B,$B31,'9AllSAAct'!AS:AS) -> 386 | J31: =SUMIF('9AllSAAct'!$B:$B,$B31,'9AllSAAct'!AT:AT) -> 381 | K31: =J31/I31% -> 98.704663 | L31: =C31+F31+I31 -> 1505 | M31: =D31+G31+J31 -> 1490 | N31: =M31/L31% -> 99.003322
A32: 28 | B32: Puducherry | C32: =SUMIF('1UniNo'!B:B,B32,'1UniNo'!N:N) -> 4 | D32: =SUMIF('2University-Specialisation'!B:B,B32,'2University-Specialisation'!W:W) -> 4 | E32: =D32/C32% -> 100 | F32: =SUMIF('8CollegeAct'!B:B,B32,'8CollegeAct'!C:C) -> 79 | G32: =SUMIF('5ManagementCollegeNo'!B:B,B32,'5ManagementCollegeNo'!G:G) -> 69 | H32: =G32/F32% -> 87.341772 | I32: =SUMIF('9AllSAAct'!$B:$B,$B32,'9AllSAAct'!AS:AS) -> 14 | J32: =SUMIF('9AllSAAct'!$B:$B,$B32,'9AllSAAct'!AT:AT) -> 13 | K32: =J32/I32% -> 92.857143 | L32: =C32+F32+I32 -> 97 | M32: =D32+G32+J32 -> 86 | N32: =M32/L32% -> 88.659794
A33: 29 | B33: Punjab | C33: =SUMIF('1UniNo'!B:B,B33,'1UniNo'!N:N) -> 32 | D33: =SUMIF('2University-Specialisation'!B:B,B33,'2University-Specialisation'!W:W) -> 32 | E33: =D33/C33% -> 100 | F33: =SUMIF('8CollegeAct'!B:B,B33,'8CollegeAct'!C:C) -> 1079 | G33: =SUMIF('5ManagementCollegeNo'!B:B,B33,'5ManagementCollegeNo'!G:G) -> 1006 | H33: =G33/F33% -> 93.234476 | I33: =SUMIF('9AllSAAct'!$B:$B,$B33,'9AllSAAct'!AS:AS) -> 421 | J33: =SUMIF('9AllSAAct'!$B:$B,$B33,'9AllSAAct'!AT:AT) -> 344 | K33: =J33/I33% -> 81.710214 | L33: =C33+F33+I33 -> 1532 | M33: =D33+G33+J33 -> 1382 | N33: =M33/L33% -> 90.208877
A34: 30 | B34: Rajasthan | C34: =SUMIF('1UniNo'!B:B,B34,'1UniNo'!N:N) -> 89 | D34: =SUMIF('2University-Specialisation'!B:B,B34,'2University-Specialisation'!W:W) -> 85 | E34: =D34/C34% -> 95.505618 | F34: =SUMIF('8CollegeAct'!B:B,B34,'8CollegeAct'!C:C) -> 3380 | G34: =SUMIF('5ManagementCollegeNo'!B:B,B34,'5ManagementCollegeNo'!G:G) -> 3101 | H34: =G34/F34% -> 91.745562 | I34: =SUMIF('9AllSAAct'!$B:$B,$B34,'9AllSAAct'!AS:AS) -> 567 | J34: =SUMIF('9AllSAAct'!$B:$B,$B34,'9AllSAAct'!AT:AT) -> 409 | K34: =J34/I34% -> 72.134039 | L34: =C34+F34+I34 -> 4036 | M34: =D34+G34+J34 -> 3595 | N34: =M34/L34% -> 89.07334
A35: 31 | B35: Sikkim | C35: =SUMIF('1UniNo'!B:B,B35,'1UniNo'!N:N) -> 8 | D35: =SUMIF('2University-Specialisation'!B:B,B35,'2University-Specialisation'!W:W) -> 7 | E35: =D35/C35% -> 87.5 | F35: =SUMIF('8CollegeAct'!B:B,B35,'8CollegeAct'!C:C) -> 22 | G35: =SUMIF('5ManagementCollegeNo'!B:B,B35,'5ManagementCollegeNo'!G:G) -> 19 | H35: =G35/F35% -> 86.363636 | I35: =SUMIF('9AllSAAct'!$B:$B,$B35,'9AllSAAct'!AS:AS) -> 8 | J35: =SUMIF('9AllSAAct'!$B:$B,$B35,'9AllSAAct'!AT:AT) -> 8 | K35: =J35/I35% -> 100 | L35: =C35+F35+I35 -> 38 | M35: =D35+G35+J35 -> 34 | N35: =M35/L35% -> 89.473684
A36: 32 | B36: Tamil Nadu | C36: =SUMIF('1UniNo'!B:B,B36,'1UniNo'!N:N) -> 59 | D36: =SUMIF('2University-Specialisation'!B:B,B36,'2University-Specialisation'!W:W) -> 59 | E36: =D36/C36% -> 100 | F36: =SUMIF('8CollegeAct'!B:B,B36,'8CollegeAct'!C:C) -> 2610 | G36: =SUMIF('5ManagementCollegeNo'!B:B,B36,'5ManagementCollegeNo'!G:G) -> 2608 | H36: =G36/F36% -> 99.923372 | I36: =SUMIF('9AllSAAct'!$B:$B,$B36,'9AllSAAct'!AS:AS) -> 914 | J36: =SUMIF('9AllSAAct'!$B:$B,$B36,'9AllSAAct'!AT:AT) -> 908 | K36: =J36/I36% -> 99.343545 | L36: =C36+F36+I36 -> 3583 | M36: =D36+G36+J36 -> 3575 | N36: =M36/L36% -> 99.776723
... A41: 37 | B41: West Bengal | C41: =SUMIF('1UniNo'!B:B,B41,'1UniNo'!N:N) -> 47 | D41: =SUMIF('2University-Specialisation'!B:B,B41,'2University-Specialisation'!W:W) -> 47 | E41: =D41/C41% -> 100 | F41: =SUMIF('8CollegeAct'!B:B,B41,'8CollegeAct'!C:C) -> 1411 | G41: =SUMIF('5ManagementCollegeNo'!B:B,B41,'5ManagementCollegeNo'!G:G) -> 1409 | H41: =G41/F41% -> 99.858257 | I41: =SUMIF('9AllSAAct'!$B:$B,$B41,'9AllSAAct'!AS:AS) -> 477 | J41: =SUMIF('9AllSAAct'!$B:$B,$B41,'9AllSAAct'!AT:AT) -> 477 | K41: =J41/I41% -> 100 | L41: =C41+F41+I41 -> 1935 | M41: =D41+G41+J41 -> 1933 | N41: =M41/L41% -> 99.896641
A42: All India | C42: =SUM(C5:C41) -> 1043 | D42: =SUM(D5:D41) -> 1019 | E42: =D42/C42% -> 97.698945 | F42: =SUM(F5:F41) -> 42343 | G42: =SUM(G5:G41) -> 39955 | H42: =G42/F42% -> 94.360343 | I42: =SUM(I5:I41) -> 11779 | J42: =SUM(J5:J41) -> 9599 | K42: =J42/I42% -> 81.492487 | L42: =C42+F42+I42 -> 55165 | M42: =D42+G42+J42 -> 50573 | N42: =M42/L42% -> 91.675881
A43: * Lakshadweep dose not have any University/Colleges & Stand Alone Institutions. However 3 PG/Off-shore campus of University of Calicut, Malappuram are functiong from Lakshadweep.

Sheet 2University-Specialisation
B1: Table 2. | C1: State & Specialisation-wise Number of Universities (Based on actual Response) | M1: =C1 -> State & Specialisation-wise Number of Universities (Based on actual Response)
A2: Sl. No. | B2: State/UTs | C2: General | D2: Agriculture | E2: Cultural Studies | F2: Education | G2: Fine Arts | H2: Fisheries | I2: Gandhian / Religious Studies | J2: Journalism & Mass Communication | K2: Language | L2: Law | M2: Management | N2: Medical | O2: Oriental Learning | P2: Rural Development | Q2: Sanskrit | R2: Science | S2: Sports / Yoga / Physical Education | T2: Technical | U2: Veterinary | V2: Others | W2: Grand Total
A3: 1 | B3: 2 | C3: 3 | D3: 4 | E3: 5 | F3: 6 | G3: 7 | H3: 8 | I3: 9 | J3: 10 | K3: 11 | L3: 12 | M3: 13 | N3: 14 | O3: 15 | P3: 16 | Q3: 17 | R3: 18 | S3: 19 | T3: 20 | U3: 21 | V3: 22 | W3: 23
A4: 1 | B4: Andhra Pradesh | C4: 17 | D4: 3 | K4: 1 | L4: 1 | M4: 1 | N4: 2 | P4: 1 | Q4: 1 | R4: 2 | T4: 9 | U4: 1 | W4: =SUM(C4:V4) -> 39
A5: 2 | B5: Arunachal Pradesh | C5: 6 | T5: 3 | V5: 1 | W5: =SUM(C5:V5) -> 10
A6: 3 | B6: Assam | C6: 13 | D6: 1 | E6: 1 | L6: 1 | M6: 1 | N6: 1 | Q6: 1 | T6: 6 | V6: 1 | W6: =SUM(C6:V6) -> 26
A7: 4 | B7: Bihar | C7: 20 | D7: 1 | F7: 1 | L7: 1 | M7: 3 | N7: 2 | O7: 1 | P7: 1 | Q7: 1 | T7: 3 | V7: 1 | W7: =SUM(C7:V7) -> 35
A8: 5 | B8: Chandigarh | C8: 1 | N8: 1 | T8: 1 | W8: =SUM(C8:V8) -> 3
A9: 6 | B9: Chhattisgarh | C9: 14 | D9: 1 | G9: 1 | J9: 1 | L9: 1 | M9: 1 | N9: 2 | R9: 1 | T9: 4 | U9: 1 | V9: 1 | W9: =SUM(C9:V9) -> 28
A10: 7 | B10: Delhi | C10: 7 | D10: 1 | E10: 1 | F10: 1 | L10: 2 | N10: 2 | Q10: 1 | R10: 1 | T10: 10 | V10: 1 | W10: =SUM(C10:V10) -> 27
A11: 8 | B11: Goa | C11: 1 | T11: 2 | W11: =SUM(C11:V11) -> 3
A12: 9 | B12: Gujarat | C12: 42 | D12: 4 | F12: 1 | L12: 1 | N12: 5 | Q12: 1 | R12: 2 | S12: 2 | T12: 12 | U12: 1 | V12: 5 | W12: =SUM(C12:V12) -> 76
A13: 10 | B13: Haryana | C13: 31 | D13: 2 | F13: 1 | G13: 1 | K13: 1 | L13: 1 | M13: 3 | N13: 2 | T13: 4 | U13: 2 | V13: 3 | W13: =SUM(C13:V13) -> 51
A14: 11 | B14: Himachal Pradesh | C14: 14 | D14: 2 | L14: 1 | M14: 2 | T14: 7 | V14: 1 | W14: =SUM(C14:V14) -> 27
A15: 12 | B15: Jammu and Kashmir | C15: 6 | D15: 2 | E15: 1 | M15: 3 | T15: 3 | W15: =SUM(C15:V15) -> 15
A16: 13 | B16: Jharkhand | C16: 20 | E16: 1 | L16: 1 | M16: 1 | N16: 1 | T16: 6 | V16: 1 | W16: =SUM(C16:V16) -> 31
A17: 14 | B17: Karnataka | C17: 35 | D17: 4 | G17: 2 | K17: 1 | L17: 1 | M17: 1 | N17: 8 | Q17: 1 | R17: 2 | T17: 9 | U17: 1 | V17: 4 | W17: =SUM(C17:V17) -> 69
A18: 15 | B18: Kerala | C18: 7 | D18: 1 | H18: 1 | K18: 1 | L18: 1 | M18: 2 | N18: 2 | R18: 1 | T18: 5 | U18: 1 | V18: 1 | W18: =SUM(C18:V18) -> 23
A19: 16 | B19: Ladakh | O19: 1 | W19: =SUM(C19:V19) -> 1
A20: 17 | B20: Madhya Pradesh | C20: 33 | D20: 2 | F20: 1 | G20: 2 | J20: 1 | K20: 2 | L20: 1 | M20: 4 | N20: 2 | Q20: 1 | R20: 1 | T20: 6 | U20: 1 | V20: 2 | W20: =SUM(C20:V20) -> 59
A21: 18 | B21: Maharashtra | C21: 27 | D21: 5 | E21: 1 | F21: 1 | H21: 2 | K21: 1 | L21: 2 | M21: 3 | N21: 7 | Q21: 1 | R21: 2 | T21: 10 | V21: 3 | W21: =SUM(C21:V21) -> 65
A22: 19 | B22: Manipur | C22: 2 | F22: 1 | M22: 1 | T22: 3 | W22: =SUM(C22:V22) -> 7
A23: 20 | B23: Meghalaya | C23: 3 | H23: 1 | M23: 3 | T23: 2 | W23: =SUM(C23:V23) -> 9
A24: 21 | B24: Mizoram | C24: 2 | T24: 1 | W24: =SUM(C24:V24) -> 3
A25: 22 | B25: Nagaland | C25: 3 | T25: 2 | W25: =SUM(C25:V25) -> 5
A26: 23 | B26: Odisha | C26: 14 | D26: 1 | L26: 1 | M26: 2 | N26: 3 | Q26: 1 | R26: 2 | T26: 7 | V26: 1 | W26: =SUM(C26:V26) -> 32
A27: 24 | B27: Puducherry | C27: 1 | N27: 2 | T27: 1 | W27: =SUM(C27:V27) -> 4
A28: 25 | B28: Punjab | C28: 17 | D28: 1 | L28: 1 | M28: 3 | N28: 4 | R28: 2 | T28: 3 | U28: 1 | W28: =SUM(C28:V28) -> 32
A29: 26 | B29: Rajasthan | C29: 50 | D29: 6 | I29: 1 | J29: 1 | L29: 1 | M29: 1 | N29: 8 | Q29: 1 | R29: 1 | T29: 11 | U29: 1 | V29: 3 | W29: =SUM(C29:V29) -> 85
A30: 27 | B30: Sikkim | C30: 4 | T30: 2 | V30: 1 | W30: =SUM(C30:V30) -> 7
A31: 28 | B31: Tamil Nadu | C31: 22 | H31: 1 | K31: 2 | L31: 2 | M31: 1 | N31: 4 | P31: 1 | R31: 2 | S31: 2 | T31: 18 | U31: 1 | V31: 3 | W31: =SUM(C31:V31) -> 59
A32: 29 | B32: Telangana | C32: 11 | D32: 1 | G32: 1 | K32: 1 | L32: 1 | N32: 2 | Q32: 1 | S32: 1 | T32: 4 | U32: 1 | W32: =SUM(C32:V32) -> 24
A33: 30 | B33: Tripura | C33: 2 | G33: 1 | T33: 1 | W33: =SUM(C33:V33) -> 4
A34: 31 | B34: Uttar Pradesh | C34: 47 | D34: 5 | F34: 1 | G34: 2 | K34: 1 | L34: 1 | N34: 2 | O34: 1 | T34: 13 | U34: 2 | V34: 2 | W34: =SUM(C34:V34) -> 77
A35: 32 | B35: Uttarakhand | C35: 21 | D35: 4 | F35: 2 | G35: 1 | M35: 1 | N35: 2 | Q35: 1 | T35: 3 | V35: 1 | W35: =SUM(C35:V35) -> 36
A36: 33 | B36: West Bengal | C36: 29 | D36: 2 | F36: 1 | L36: 1 | M36: 1 | N36: 2 | O36: 1 | R36: 3 | T36: 6 | V36: 1 | W36: =SUM(C36:V36) -> 47
A37: All India | C37: =SUM(C4:C36) -> 522 | D37: =SUM(D4:D36) -> 49 | E37: =SUM(E4:E36) -> 5 | F37: =SUM(F4:F36) -> 11 | G37: =SUM(G4:G36) -> 11 | H37: =SUM(H4:H36) -> 5 | I37: =SUM(I4:I36) -> 1 | J37: =SUM(J4:J36) -> 3 | ... W37: =SUM(W4:W36) -> 1019

Sheet 3Collegerange
B1: Table 3. | C1: State-wise Distribution of Districts in Different Ranges of number of Colleges
A2: Sl. No. | B2: State/UTs | C2: Number of Colleges
C3: 44075 | D3: 10-19 | E3: 20-49 | F3: 50-99 | G3: 100-199 | H3: 200-299 | I3: 300-399 | J3: 400-499 | K3: 500-999 | L3: More than 1000
A4: 1 | B4: 2 | C4: 3 | D4: 4 | E4: 5 | F4: 6 | G4: 7 | H4: 8 | I4: 9 | J4: 10 | K4: 11 | L4: 12
A5: 1 | B5: Andaman and Nicobar Islands | C5: 3 | D5: 0 | E5: 0 | F5: 0 | G5: 0 | H5: 0 | I5: 0 | J5: 0 | K5: 0 | L5: 0
A6: 2 | B6: Andhra Pradesh | C6: 0 | D6: 0 | E6: 0 | F6: 0 | G6: 5 | H6: 7 | I6: 1 | J6: 0 | K6: 0 | L6: 0
A7: 3 | B7: Arunachal Pradesh | C7: 15 | D7: 1 | E7: 0 | F7: 0 | G7: 0 | H7: 0 | I7: 0 | J7: 0 | K7: 0 | L7: 0
A8: 4 | B8: Assam | C8: 7 | D8: 14 | E8: 9 | F8: 1 | G8: 0 | H8: 0 | I8: 0 | J8: 0 | K8: 0 | L8: 0
A9: 5 | B9: Bihar | C9: 7 | D9: 15 | E9: 14 | F9: 1 | G9: 1 | H9: 0 | I9: 0 | J9: 0 | K9: 0 | L9: 0
A10: 6 | B10: Chandigarh | C10: 0 | D10: 0 | E10: 1 | F10: 0 | G10: 0 | H10: 0 | I10: 0 | J10: 0 | K10: 0 | L10: 0
A11: 7 | B11: Chhattisgarh | C11: 10 | D11: 7 | E11: 6 | F11: 1 | G11: 3 | H11: 0 | I11: 0 | J11: 0 | K11: 0 | L11: 0
A12: 8 | B12: Dadra and Nagar Haveli | C12: 1 | D12: 0 | E12: 0 | F12: 0 | G12: 0 | H12: 0 | I12: 0 | J12: 0 | K12: 0 | L12: 0
A13: 9 | B13: Daman and Diu | C13: 2 | D13: 0 | E13: 0 | F13: 0 | G13: 0 | H13: 0 | I13: 0 | J13: 0 | K13: 0 | L13: 0
A14: 10 | B14: Delhi | C14: 2 | D14: 4 | E14: 4 | F14: 0 | G14: 0 | H14: 0 | I14: 0 | J14: 0 | K14: 0 | L14: 0
A15: 11 | B15: Goa | C15: 0 | D15: 0 | E15: 2 | F15: 0 | G15: 0 | H15: 0 | I15: 0 | J15: 0 | K15: 0 | L15: 0
A16: 12 | B16: Gujarat | C16: 1 | D16: 4 | E16: 13 | F16: 6 | G16: 8 | H16: 1 | I16: 0 | J16: 0 | K16: 0 | L16: 0
... A41: 37 | B41: West Bengal | C41: 3 | D41: 0 | E41: 7 | F41: 8 | G41: 4 | H41: 0 | I41: 0 | J41: 0 | K41: 0 | L41: 0
A42: All India | C42: =SUM(C5:C41) -> 149 | D42: =SUM(D5:D41) -> 95 | E42: =SUM(E5:E41) -> 186 | F42: =SUM(F5:F41) -> 134 | G42: =SUM(G5:G41) -> 97 | H42: =SUM(H5:H41) -> 28 | I42: =SUM(I5:I41) -> 6 | J42: =SUM(J5:J41) -> 2 | ... L42: =SUM(L5:L41) -> 1

Sheet 4CollegeIndicator
A1: Table 4. Number of Colleges per Lakh Population (18-23 Years), Average Enrolment per College
A2: Sl. No. | B2: State/UTs | C2: No. of Colleges | D2: No. of Colleges per lakh Population | E2: Average Enrolment per College | F2: Zone | G2: Population
A3: 1 | B3: 2 | C3: 3 | D3: 4 | E3: 5
A4: 1 | B4: Andaman and Nicobar Islands | C4: 8 | D4: 15.781894 | E4: 738.5 | F4: UT | G4: =SUMIF('[1]19pop2014'!$B$5:$B$40,B4,'[1]19pop2014'!$E$5:$E$40) -> #VALUE!
A5: 2 | B5: Andhra Pradesh | C5: 2750 | D5: 51.038485 | E5: 546.52739 | F5: South | G5: =SUMIF('[1]19pop2014'!$B$5:$B$40,B5,'[1]19pop2014'!$E$5:$E$40) -> #VALUE!
A6: 3 | B6: Arunachal Pradesh | C6: 39 | D6: 24.721252 | E6: 552.97368 | F6: North-East | G6: =SUMIF('[1]19pop2014'!$B$5:$B$40,B6,'[1]19pop2014'!$E$5:$E$40) -> #VALUE!
A7: 4 | B7: Assam | C7: 558 | D7: 14.84071 | E7: 870.01689 | F7: North-East | G7: =SUMIF('[1]19pop2014'!$B$5:$B$40,B7,'[1]19pop2014'!$E$5:$E$40) -> #VALUE!
A8: 5 | B8: Bihar | C8: 874 | D8: 7.269127 | E8: 1703.051 | F8: East | G8: =SUMIF('[1]19pop2014'!$B$5:$B$40,B8,'[1]19pop2014'!$E$5:$E$40) -> #VALUE!
A9: 6 | B9: Chandigarh | C9: 25 | D9: 12.221891 | E9: 2022.24 | F9: UT | G9: =SUMIF('[1]19pop2014'!$B$5:$B$40,B9,'[1]19pop2014'!$E$5:$E$40) -> #VALUE!
A10: 7 | B10: Chhattisgarh | C10: 810 | D10: 25.551309 | E10: 557.02107 | F10: East | G10: =SUMIF('[1]19pop2014'!$B$5:$B$40,B10,'[1]19pop2014'!$E$5:$E$40) -> #VALUE!
A11: 8 | B11: Dadra and Nagar Haveli | C11: 8 | D11: 11.813698 | E11: 761 | F11: UT | G11: =SUMIF('[1]19pop2014'!$B$5:$B$40,B11,'[1]19pop2014'!$E$5:$E$40) -> #VALUE!
A12: 9 | B12: Daman and Diu | C12: 10 | D12: 15.45834 | E12: 393.2 | F12: UT | G12: =SUMIF('[1]19pop2014'!$B$5:$B$40,B12,'[1]19pop2014'!$E$5:$E$40) -> #VALUE!
A13: 10 | B13: Delhi | C13: 179 | D13: 7.5875396 | E13: 1620.0977 | F13: North | G13: =SUMIF('[1]19pop2014'!$B$5:$B$40,B13,'[1]19pop2014'!$E$5:$E$40) -> #VALUE!
A14: 11 | B14: Goa | C14: 58 | D14: 31.255389 | E14: 670.32759 | F14: West | G14: =SUMIF('[1]19pop2014'!$B$5:$B$40,B14,'[1]19pop2014'!$E$5:$E$40) -> #VALUE!
A15: 12 | B15: Gujarat | C15: 2275 | D15: 31.396927 | E15: 527.68778 | F15: West | G15: =SUMIF('[1]19pop2014'!$B$5:$B$40,B15,'[1]19pop2014'!$E$5:$E$40) -> #VALUE!
... A21: 18 | B21: Kerala | C21: 1417 | D21: 48.301966 | E21: 574.73267 | F21: South | G21: =SUMIF('[1]19pop2014'!$B$5:$B$40,B21,'[1]19pop2014'!$E$5:$E$40) -> #VALUE!
A22: 19 | B22: Ladakh | C22: 5 | D22: 13.665582 | E22: 479.6
A23: 20 | B23: Lakshadweep | F23: UT | G23: =SUMIF('[1]19pop2014'!$B$5:$B$40,B23,'[1]19pop2014'!$E$5:$E$40) -> #VALUE!
A24: 21 | B24: Madhya Pradesh | C24: 2411 | D24: 26.7264 | E24: 771.44707 | F24: North | G24: =SUMIF('[1]19pop2014'!$B$5:$B$40,B24,'[1]19pop2014'!$E$5:$E$40) -> #VALUE!
A25: 22 | B25: Maharashtra | C25: 4494 | D25: 34.063299 | E25: 669.65265 | F25: West | G25: =SUMIF('[1]19pop2014'!$B$5:$B$40,B25,'[1]19pop2014'!$E$5:$E$40) -> #VALUE!
A26: 23 | B26: Manipur | C26: 102 | D26: 31.388189 | E26: 1056.4158 | F26: North-East | G26: =SUMIF('[1]19pop2014'!$B$5:$B$40,B26,'[1]19pop2014'!$E$5:$E$40) -> #VALUE!
A27: 24 | B27: Meghalaya | C27: 67 | D27: 19.985622 | E27: 1105.386 | F27: North-East | G27: =SUMIF('[1]19pop2014'!$B$5:$B$40,B27,'[1]19pop2014'!$E$5:$E$40) -> #VALUE!
A28: 25 | B28: Mizoram | C28: 35 | D28: 27.536722 | E28: 559.42857 | F28: North-East | G28: =SUMIF('[1]19pop2014'!$B$5:$B$40,B28,'[1]19pop2014'!$E$5:$E$40) -> #VALUE!
A29: 26 | B29: Nagaland | C29: 67 | D29: 27.798523 | E29: 507.0303 | F29: North-East | G29: =SUMIF('[1]19pop2014'!$B$5:$B$40,B29,'[1]19pop2014'!$E$5:$E$40) -> #VALUE!
A30: 27 | B30: Odisha | C30: 1087 | D30: 23.679838 | E30: 658.64717 | F30: East | G30: =SUMIF('[1]19pop2014'!$B$5:$B$40,B30,'[1]19pop2014'!$E$5:$E$40) -> #VALUE!
A31: 28 | B31: Puducherry | C31: 79 | D31: 45.686659 | E31: 667.68116 | F31: UT | G31: =SUMIF('[1]19pop2014'!$B$5:$B$40,B31,'[1]19pop2014'!$E$5:$E$40) -> #VALUE!
A32: 29 | B32: Punjab | C32: 1079 | D32: 35.048604 | E32: 521.34891 | F32: North | G32: =SUMIF('[1]19pop2014'!$B$5:$B$40,B32,'[1]19pop2014'!$E$5:$E$40) -> #VALUE!
A33: 30 | B33: Rajasthan | C33: 3380 | D33: 36.914462 | E33: 517.23025 | F33: West | G33: =SUMIF('[1]19pop2014'!$B$5:$B$40,B33,'[1]19pop2014'!$E$5:$E$40) -> #VALUE!
A34: 31 | B34: Sikkim | C34: 22 | D34: 28.731504 | E34: 633.89474 | F34: North-East | G34: =SUMIF('[1]19pop2014'!$B$5:$B$40,B34,'[1]19pop2014'!$E$5:$E$40) -> #VALUE!
A35: 32 | B35: Tamil Nadu | C35: 2610 | D35: 38.086383 | E35: 872.42715 | F35: South | G35: =SUMIF('[1]19pop2014'!$B$5:$B$40,B35,'[1]19pop2014'!$E$5:$E$40) -> #VALUE!
A36: 33 | B36: Telangana | C36: 2071 | D36: 53.071959 | E36: 545.16014
A37: 34 | B37: Tripura | C37: 53 | D37: 12.413195 | E37: 1174.6604 | F37: North-East | G37: =SUMIF('[1]19pop2014'!$B$5:$B$40,B37,'[1]19pop2014'!$E$5:$E$40) -> #VALUE!
A38: 35 | B38: Uttar Pradesh | C38: 7788 | D38: 30.795565 | E38: 691.99172 | F38: North | G38: =SUMIF('[1]19pop2014'!$B$5:$B$40,B38,'[1]19pop2014'!$E$5:$E$40) -> #VALUE!
A39: 36 | B39: Uttarakhand | C39: 454 | D39: 38.190189 | E39: 633.90594 | F39: North | G39: =SUMIF('[1]19pop2014'!$B$5:$B$40,B39,'[1]19pop2014'!$E$5:$E$40) -> #VALUE!
A40: 37 | B40: West Bengal | C40: 1411 | D40: 13.024762 | E40: 1179.3669 | F40: East | G40: =SUMIF('[1]19pop2014'!$B$5:$B$40,B40,'[1]19pop2014'!$E$5:$E$40) -> #VALUE!
A41: All India | C41: 42343 | D41: 29.750148 | E41: 679.60803 | G41: =SUM(G4:G40) -> #VALUE!

Sheet 4aCollegeSpec
A1: Table 4a. | C1: Specialisation-wise number of Colleges (Based on actual Response) | N1: =C1 -> Specialisation-wise number of Colleges (Based on actual Response) | X1: =C1 -> Specialisation-wise number of Colleges (Based on actual Response)
A2: Sl. No. | B2: State/UTs | C2: General | D2: Agriculture | E2: Architecture | F2: Arts | G2: Commerce | H2: Computer Application | I2: Education/Teacher Education | J2: Engineering & Technology | K2: Fine Arts | L2: Fisheries | M2: Home Sceince | N2: Hotel & Tourism Management | O2: Journalism & Mass Communication | P2: Law | Q2: Management | R2: Medical-Allopathy | S2: Medical-Ayurveda | T2: Medical-Dental | U2: Medical-Homeopathy | V2: Medical-Others | W2: Nursing | X2: Oriental Learning | Y2: Para Medical | Z2: Pharmacy | AA2: Physiotherapy | AB2: Sanskrit | AC2: Science | AD2: Social Work | AE2: Sports/Yoga/Physical Education | AF2: Veterinary | AG2: Others | AH2: Grand Total
A3: 1 | B3: 2 | C3: 3 | D3: 4 | E3: 5 | F3: 6 | G3: 7 | H3: 8 | I3: 9 | J3: 10 | K3: 11 | L3: 12 | M3: 13 | N3: 14 | O3: 15 | P3: 16 | Q3: 17 | R3: 18 | S3: 19 | T3: 20 | U3: 21 | V3: 22 | W3: 23 | X3: 24 | Y3: 25 | Z3: 26 | AA3: 27 | AB3: 28 | AC3: 29 | AD3: 30 | AE3: 31 | AF3: 32 | AG3: 33 | AH3: 34
A4: 1 | B4: Andaman and Nicobar Islands | C4: 4 | I4: 1 | R4: 1 | V4: 1 | AC4: 1 | AH4: =SUM(C4:AG4) -> 8
A5: 2 | B5: Andhra Pradesh | C5: 1811 | D5: 28 | E5: 4 | F5: 8 | G5: 4 | H5: 9 | I5: 76 | J5: 273 | L5: 1 | M5: 1 | N5: 6 | P5: 15 | Q5: 42 | R5: 11 | S5: 2 | T5: 10 | U5: 1 | V5: 8 | W5: 66 | X5: 4 | Y5: 7 | Z5: 70 | AA5: 11 | AB5: 2 | AC5: 4 | AE5: 12 | AF5: 3 | AG5: 12 | AH5: =SUM(C5:AG5) -> 2501
A6: 3 | B6: Arunachal Pradesh | C6: 26 | D6: 1 | F6: 1 | I6: 6 | P6: 2 | R6: 1 | U6: 1 | AH6: =SUM(C6:AG6) -> 38
A7: 4 | B7: Assam | C7: 364 | D7: 2 | E7: 1 | F7: 37 | G7: 11 | I7: 43 | J7: 6 | K7: 2 | L7: 1 | N7: 1 | P7: 19 | Q7: 2 | R7: 5 | S7: 1 | T7: 1 | U7: 2 | W7: 10 | Y7: 3 | Z7: 6 | AA7: 1 | AB7: 1 | AC7: 6 | AD7: 1 | AE7: 1 | AF7: 2 | AG7: 4 | AH7: =SUM(C7:AG7) -> 533
A8: 5 | B8: Bihar | C8: 511 | D8: 6 | F8: 4 | G8: 1 | H8: 3 | I8: 184 | J8: 55 | K8: 1 | P8: 16 | Q8: 2 | R8: 9 | S8: 1 | T8: 2 | U8: 1 | V8: 2 | W8: 5 | Y8: 2 | Z8: 3 | AB8: 49 | AF8: 1 | AG8: 5 | AH8: =SUM(C8:AG8) -> 863
A9: 6 | B9: Chandigarh | C9: 9 | E9: 1 | G9: 1 | I9: 4 | J9: 2 | K9: 1 | M9: 1 | S9: 1 | U9: 1 | V9: 1 | AE9: 2 | AF9: 1 | AH9: =SUM(C9:AG9) -> 25
A10: 7 | B10: Chhattisgarh | C10: 481 | D10: 25 | E10: 1 | F10: 6 | G10: 2 | H10: 10 | I10: 55 | J10: 61 | K10: 3 | L10: 1 | P10: 9 | R10: 4 | S10: 6 | T10: 6 | U10: 3 | V10: 6 | W10: 83 | Z10: 19 | AA10: 3 | AB10: 4 | AC10: 7 | AE10: 3 | AF10: 6 | AG10: 3 | AH10: =SUM(C10:AG10) -> 807
A11: 8 | B11: Dadra and Nagar Haveli | C11: 3 | I11: 1 | J11: 1 | W11: 1 | Z11: 1 | AG11: 1 | AH11: =SUM(C11:AG11) -> 8
A12: 9 | B12: Daman and Diu | C12: 3 | H12: 1 | I12: 1 | J12: 3 | T12: 1 | W12: 1 | AH12: =SUM(C12:AG12) -> 10
A13: 10 | B13: Delhi | C13: 91 | E13: 2 | G13: 1 | H13: 1 | I13: 15 | J13: 12 | K13: 2 | M13: 1 | O13: 1 | P13: 1 | Q13: 8 | R13: 9 | S13: 2 | T13: 2 | U13: 2 | V13: 3 | W13: 7 | Y13: 1 | Z13: 1 | AE13: 2 | AG13: 10 | AH13: =SUM(C13:AG13) -> 174
A14: 11 | B14: Goa | C14: 28 | D14: 2 | E14: 1 | G14: 1 | I14: 3 | J14: 6 | K14: 2 | M14: 1 | N14: 2 | P14: 2 | R14: 2 | S14: 1 | T14: 1 | U14: 1 | W14: 2 | Z14: 1 | AG14: 2 | AH14: =SUM(C14:AG14) -> 58
A15: 12 | B15: Gujarat | C15: 899 | D15: 32 | E15: 15 | F15: 110 | G15: 87 | H15: 91 | I15: 217 | J15: 207 | K15: 4 | L15: 3 | M15: 3 | N15: 4 | O15: 1 | P15: 52 | Q15: 75 | R15: 21 | S15: 23 | T15: 9 | U15: 29 | V15: 10 | W15: 74 | Y15: 11 | Z15: 51 | AA15: 45 | AB15: 21 | AC15: 107 | AD15: 7 | AE15: 3 | AF15: 6 | AG15: 41 | AH15: =SUM(C15:AG15) -> 2258
A16: 13 | B16: Haryana | C16: 519 | D16: 4 | E16: 9 | F16: 3 | H16: 4 | I16: 257 | J16: 82 | N16: 1 | P16: 16 | Q16: 20 | R16: 4 | S16: 7 | T16: 9 | U16: 1 | V16: 8 | W16: 31 | Z16: 34 | AA16: 5 | AB16: 1 | AC16: 3 | AF16: 8 | AG16: 8 | AH16: =SUM(C16:AG16) -> 1034
A17: 14 | B17: Himachal Pradesh | C17: 197 | F17: 2 | H17: 2 | I17: 39 | J17: 18 | K17: 1 | N17: 4 | P17: 5 | Q17: 4 | R17: 5 | S17: 2 | T17: 5 | U17: 1 | V17: 2 | W17: 20 | X17: 1 | Z17: 16 | AB17: 16 | AC17: 1 | AE17: 1 | AG17: 2 | AH17: =SUM(C17:AG17) -> 344
A18: 15 | B18: Jammu and Kashmir | C18: 188 | D18: 3 | E18: 1 | F18: 1 | G18: 1 | H18: 3 | I18: 70 | J18: 8 | L18: 1 | P18: 5 | Q18: 1 | R18: 6 | S18: 2 | T18: 3 | V18: 3 | W18: 6 | X18: 3 | Y18: 2 | AA18: 1 | AE18: 1 | AF18: 1 | AG18: 3 | AH18: =SUM(C18:AG18) -> 313
A19: 16 | B19: Jharkhand | C19: 181 | F19: 8 | G19: 1 | I19: 80 | J19: 16 | P19: 6 | Q19: 2 | R19: 2 | S19: 1 | T19: 3 | U19: 3 | V19: 4 | W19: 3 | Z19: 1 | AB19: 4 | AE19: 1 | AG19: 1 | AH19: =SUM(C19:AG19) -> 317
A20: 17 | B20: Karnataka | C20: 2559 | D20: 20 | E20: 15 | F20: 73 | G20: 112 | H20: 23 | I20: 123 | J20: 178 | K20: 11 | L20: 1 | M20: 2 | N20: 10 | O20: 2 | P20: 70 | Q20: 66 | R20: 39 | S20: 69 | T20: 38 | U20: 13 | V20: 39 | W20: 256 | X20: 2 | Y20: 29 | Z20: 54 | AA20: 38 | AB20: 23 | AC20: 13 | AD20: 12 | AE20: 15 | AF20: 5 | AG20: 61 | AH20: =SUM(C20:AG20) -> 3971
A21: 18 | B21: Kerala | C21: 712 | D21: 5 | E21: 19 | F21: 22 | G21: 2 | H21: 2 | I21: 106 | J21: 119 | K21: 6 | M21: 1 | N21: 4 | P21: 12 | Q21: 33 | R21: 18 | S21: 14 | T21: 21 | U21: 6 | V21: 14 | W21: 104 | X21: 7 | Y21: 26 | Z21: 32 | AA21: 2 | AB21: 3 | AC21: 2 | AE21: 2 | AF21: 2 | AG21: 17 | AH21: =SUM(C21:AG21) -> 1313
A22: 19 | B22: Ladakh | C22: 5 | AH22: =SUM(C22:AG22) -> 5
A23: 20 | B23: Lakshadweep | C23: 0 | D23: 0 | E23: 0 | F23: 0 | G23: 0 | H23: 0 | I23: 0 | J23: 0 | K23: 0 | L23: 0 | M23: 0 | N23: 0 | O23: 0 | P23: 0 | Q23: 0 | R23: 0 | S23: 0 | T23: 0 | U23: 0 | V23: 0 | W23: 0 | X23: 0 | Y23: 0 | Z23: 0 | AA23: 0 | AB23: 0 | AC23: 0 | AD23: 0 | AE23: 0 | AF23: 0 | AG23: 0 | AH23: =SUM(C23:AG23) -> 0
A24: 21 | B24: Madhya Pradesh | C24: 1317 | D24: 11 | E24: 1 | F24: 33 | G24: 9 | H24: 15 | I24: 145 | J24: 111 | K24: 18 | M24: 1 | N24: 2 | P24: 35 | Q24: 41 | R24: 7 | S24: 6 | T24: 5 | U24: 9 | V24: 8 | W24: 55 | X24: 3 | Y24: 11 | Z24: 70 | AB24: 6 | AC24: 12 | AD24: 1 | AE24: 2 | AF24: 2 | AG24: 10 | AH24: =SUM(C24:AG24) -> 1946
A25: 22 | B25: Maharashtra | C25: 2744 | D25: 106 | E25: 57 | F25: 120 | G25: 65 | H25: 34 | I25: 172 | J25: 345 | K25: 23 | L25: 4 | M25: 11 | N25: 14 | O25: 5 | P25: 87 | Q25: 98 | R25: 38 | S25: 54 | T25: 25 | U25: 37 | V25: 26 | W25: 80 | Y25: 3 | Z25: 144 | AA25: 28 | AB25: 3 | AC25: 52 | AD25: 36 | AE25: 16 | AF25: 7 | AG25: 60 | AH25: =SUM(C25:AG25) -> 4494
A26: 23 | B26: Manipur | C26: 68 | D26: 4 | F26: 1 | I26: 9 | J26: 4 | K26: 1 | P26: 1 | Q26: 2 | T26: 1 | V26: 2 | W26: 5 | AC26: 1 | AD26: 1 | AG26: 1 | AH26: =SUM(C26:AG26) -> 101
A27: 24 | B27: Meghalaya | C27: 41 | D27: 1 | F27: 6 | G27: 1 | I27: 3 | J27: 2 | P27: 1 | W27: 1 | AC27: 1 | AH27: =SUM(C27:AG27) -> 57
A28: 25 | B28: Mizoram | C28: 26 | D28: 1 | I28: 1 | J28: 1 | P28: 1 | R28: 1 | W28: 1 | Y28: 1 | AD28: 1 | AF28: 1 | AH28: =SUM(C28:AG28) -> 35
A29: 26 | B29: Nagaland | C29: 52 | F29: 2 | I29: 6 | J29: 1 | P29: 3 | W29: 1 | AG29: 1 | AH29: =SUM(C29:AG29) -> 66
A30: 27 | B30: Odisha | C30: 724 | E30: 2 | F30: 48 | G30: 1 | H30: 9 | I30: 19 | J30: 79 | K30: 5 | N30: 10 | O30: 1 | P30: 17 | Q30: 27 | R30: 4 | S30: 3 | T30: 2 | U30: 5 | V30: 4 | W30: 12 | X30: 4 | Y30: 1 | Z30: 14 | AA30: 3 | AB30: 51 | AC30: 8 | AD30: 2 | AE30: 2 | AG30: 20 | AH30: =SUM(C30:AG30) -> 1077
A31: 28 | B31: Puducherry | C31: 21 | D31: 1 | I31: 14 | J31: 12 | K31: 1 | P31: 1 | R31: 4 | S31: 1 | T31: 2 | V31: 1 | W31: 4 | Y31: 3 | Z31: 1 | AF31: 1 | AG31: 2 | AH31: =SUM(C31:AG31) -> 69
A32: 29 | B32: Punjab | C32: 463 | D32: 1 | E32: 2 | F32: 19 | G32: 5 | H32: 19 | I32: 161 | J32: 84 | K32: 1 | N32: 9 | P32: 14 | Q32: 40 | R32: 5 | S32: 15 | T32: 12 | U32: 4 | V32: 2 | W32: 84 | Y32: 2 | Z32: 30 | AA32: 4 | AC32: 2 | AE32: 9 | AF32: 2 | AG32: 17 | AH32: =SUM(C32:AG32) -> 1006
A33: 30 | B33: Rajasthan | C33: 2137 | D33: 23 | E33: 3 | F33: 115 | G33: 4 | H33: 6 | I33: 358 | J33: 79 | K33: 2 | M33: 1 | N33: 1 | P33: 45 | Q33: 9 | R33: 9 | S33: 15 | T33: 6 | U33: 5 | V33: 7 | W33: 120 | Y33: 1 | Z33: 61 | AA33: 6 | AB33: 45 | AC33: 13 | AE33: 6 | AF33: 9 | AG33: 15 | AH33: =SUM(C33:AG33) -> 3101
A34: 31 | B34: Sikkim | C34: 10 | I34: 3 | J34: 2 | W34: 1 | Z34: 1 | AB34: 1 | AC34: 1 | AH34: =SUM(C34:AG34) -> 19
A35: 32 | B35: Tamil Nadu | C35: 1285 | D35: 34 | E35: 36 | F35: 59 | G35: 1 | H35: 6 | I35: 200 | J35: 455 | K35: 5 | L35: 6 | M35: 1 | P35: 12 | Q35: 44 | R35: 42 | S35: 6 | T35: 15 | U35: 10 | V35: 74 | W35: 132 | X35: 2 | Y35: 36 | Z35: 35 | AA35: 20 | AB35: 1 | AC35: 12 | AD35: 1 | AE35: 18 | AF35: 4 | AG35: 56 | AH35: =SUM(C35:AG35) -> 2608
A36: 33 | B36: Telangana | C36: 1431 | E36: 8 | F36: 4 | G36: 16 | H36: 1 | I36: 62 | J36: 191 | K36: 2 | N36: 19 | O36: 1 | P36: 11 | Q36: 61 | R36: 22 | S36: 3 | T36: 11 | U36: 4 | V36: 18 | W36: 44 | X36: 7 | Y36: 10 | Z36: 81 | AA36: 17 | AC36: 4 | AD36: 1 | AE36: 4 | AG36: 9 | AH36: =SUM(C36:AG36) -> 2042
A37: 34 | B37: Tripura | C37: 26 | D37: 1 | I37: 2 | J37: 9 | K37: 1 | L37: 1 | P37: 1 | R37: 2 | W37: 3 | Y37: 1 | Z37: 2 | AE37: 1 | AF37: 1 | AG37: 2 | AH37: =SUM(C37:AG37) -> 53
A38: 35 | B38: Uttar Pradesh | C38: 5573 | D38: 13 | E38: 7 | F38: 200 | G38: 3 | H38: 7 | I38: 198 | J38: 158 | K38: 5 | M38: 1 | N38: 3 | O38: 1 | P38: 134 | Q38: 83 | R38: 15 | S38: 23 | T38: 15 | U38: 8 | V38: 16 | W38: 22 | X38: 28 | Y38: 3 | Z38: 95 | AA38: 1 | AB38: 225 | AC38: 24 | AE38: 4 | AG38: 23 | AH38: =SUM(C38:AG38) -> 6888
A39: 36 | B39: Uttarakhand | C39: 245 | D39: 4 | E39: 1 | F39: 5 | H39: 2 | I39: 21 | J39: 18 | L39: 1 | M39: 1 | N39: 4 | P39: 7 | Q39: 10 | R39: 2 | S39: 10 | T39: 2 | V39: 5 | W39: 10 | X39: 4 | Y39: 4 | Z39: 12 | AB39: 28 | AC39: 2 | AE39: 3 | AF39: 1 | AG39: 2 | AH39: =SUM(C39:AG39) -> 404
A40: 37 | B40: West Bengal | C40: 757 | F40: 10 | G40: 1 | H40: 8 | I40: 360 | J40: 80 | K40: 7 | L40: 1 | N40: 5 | P40: 26 | Q40: 32 | R40: 27 | S40: 4 | T40: 5 | U40: 11 | V40: 10 | W40: 22 | Y40: 4 | Z40: 13 | AA40: 3 | AB40: 2 | AC40: 1 | AE40: 2 | AG40: 18 | AH40: =SUM(C40:AG40) -> 1409
...

Sheet 5ManagementCollegeNo
A1: Table | C1: 5. Number of Private and Government Colleges (Based on actual Response) | H1: 5(a). Enrolment in Private and Government Colleges (Based on actual Response) | M1: 5(b). Number of Colleges Established in 2019 and their Enrolment (Based on actual Response)
A2: Sl. No. | B2: State/UTs | C2: Private Un-Aided | D2: Private Aided | E2: Private Total | F2: Government | G2: Total | H2: Private Un-Aided | I2: Private Aided | J2: Private Total | K2: Government | L2: Total | M2: Private Un-Aided | O2: Private Aided | Q2: Government | S2: Total
M3: Number | N3: Enrolment | O3: Number | P3: Enrolment | Q3: Number | R3: Enrolment | S3: Number | T3: Enrolment
A4: 1 | B4: 2 | C4: 3 | D4: 4 | E4: 5 | F4: 6 | G4: 7 | H4: 3 | I4: 4 | J4: 5 | K4: 6 | L4: 7 | M4: 3 | N4: 4 | O4: 5 | P4: 6 | Q4: 7 | R4: 8 | S4: 9 | T4: 10
A5: 1 | B5: Andaman and Nicobar Islands | C5: 0 | D5: 0 | E5: =C5+D5 -> 0 | F5: 8 | G5: =E5+F5 -> 8 | H5: 0 | I5: 0 | J5: =H5+I5 -> 0 | K5: 5908 | L5: =J5+K5 -> 5908 | M5: 0 | N5: 0 | O5: 0 | P5: 0 | Q5: 0 | R5: 0 | S5: =M5+O5+Q5 -> 0 | T5: =N5+P5+R5 -> 0
A6: 2 | B6: Andhra Pradesh | C6: 2027 | D6: 166 | E6: =C6+D6 -> 2193 | F6: 308 | G6: =E6+F6 -> 2501 | H6: 1046189 | I6: 143701 | J6: =H6+I6 -> 1189890 | K6: 176975 | L6: =J6+K6 -> 1366865 | M6: 2 | N6: 129 | O6: 0 | P6: 0 | Q6: 4 | R6: 455 | S6: =M6+O6+Q6 -> 6 | T6: =N6+P6+R6 -> 584
A7: 3 | B7: Arunachal Pradesh | C7: 13 | D7: 1 | E7: =C7+D7 -> 14 | F7: 24 | G7: =E7+F7 -> 38 | H7: 4265 | I7: 673 | J7: =H7+I7 -> 4938 | K7: 16075 | L7: =J7+K7 -> 21013 | M7: 0 | N7: 0 | O7: 0 | P7: 0 | Q7: 0 | R7: 0 | S7: =M7+O7+Q7 -> 0 | T7: =N7+P7+R7 -> 0
A8: 4 | B8: Assam | C8: 66 | D8: 23 | E8: =C8+D8 -> 89 | F8: 444 | G8: =E8+F8 -> 533 | H8: 20235 | I8: 5834 | J8: =H8+I8 -> 26069 | K8: 437650 | L8: =J8+K8 -> 463719 | M8: 1 | N8: 100 | O8: 0 | P8: 0 | Q8: 0 | R8: 0 | S8: =M8+O8+Q8 -> 1 | T8: =N8+P8+R8 -> 100
A9: 5 | B9: Bihar | C9: 245 | D9: 102 | E9: =C9+D9 -> 347 | F9: 516 | G9: =E9+F9 -> 863 | H9: 78541 | I9: 145518 | J9: =H9+I9 -> 224059 | K9: 1245674 | L9: =J9+K9 -> 1469733 | M9: 1 | N9: 60 | O9: 0 | P9: 0 | Q9: 17 | R9: 1693 | S9: =M9+O9+Q9 -> 18 | T9: =N9+P9+R9 -> 1753
A10: 6 | B10: Chandigarh | C10: 2 | D10: 7 | E10: =C10+D10 -> 9 | F10: 16 | G10: =E10+F10 -> 25 | H10: 307 | I10: 30002 | J10: =H10+I10 -> 30309 | K10: 20247 | L10: =J10+K10 -> 50556 | M10: 0 | N10: 0 | O10: 0 | P10: 0 | Q10: 0 | R10: 0 | S10: =M10+O10+Q10 -> 0 | T10: =N10+P10+R10 -> 0
A11: 7 | B11: Chhattisgarh | C11: 353 | D11: 81 | E11: =C11+D11 -> 434 | F11: 373 | G11: =E11+F11 -> 807 | H11: 120866 | I11: 38781 | J11: =H11+I11 -> 159647 | K11: 289869 | L11: =J11+K11 -> 449516 | M11: 17 | N11: 1153 | O11: 4 | P11: 219 | Q11: 3 | R11: 182 | S11: =M11+O11+Q11 -> 24 | T11: =N11+P11+R11 -> 1554
A12: 8 | B12: Dadra and Nagar Haveli | C12: 5 | D12: 0 | E12: =C12+D12 -> 5 | F12: 3 | G12: =E12+F12 -> 8 | H12: 3369 | I12: 0 | J12: =H12+I12 -> 3369 | K12: 2719 | L12: =J12+K12 -> 6088 | M12: 0 | N12: 0 | O12: 0 | P12: 0 | Q12: 0 | R12: 0 | S12: =M12+O12+Q12 -> 0 | T12: =N12+P12+R12 -> 0
A13: 9 | B13: Daman and Diu | C13: 3 | D13: 1 | E13: =C13+D13 -> 4 | F13: 6 | G13: =E13+F13 -> 10 | H13: 369 | I13: 104 | J13: =H13+I13 -> 473 | K13: 3459 | L13: =J13+K13 -> 3932 | M13: 0 | N13: 0 | O13: 0 | P13: 0 | Q13: 0 | R13: 0 | S13: =M13+O13+Q13 -> 0 | T13: =N13+P13+R13 -> 0
A14: 10 | B14: Delhi | C14: 63 | D14: 14 | E14: =C14+D14 -> 77 | F14: 97 | G14: =E14+F14 -> 174 | H14: 62339 | I14: 31720 | J14: =H14+I14 -> 94059 | K14: 187838 | L14: =J14+K14 -> 281897 | M14: 0 | N14: 0 | O14: 0 | P14: 0 | Q14: 0 | R14: 0 | S14: =M14+O14+Q14 -> 0 | T14: =N14+P14+R14 -> 0
A15: 11 | B15: Goa | C15: 11 | D15: 25 | E15: =C15+D15 -> 36 | F15: 22 | G15: =E15+F15 -> 58 | H15: 3487 | I15: 20671 | J15: =H15+I15 -> 24158 | K15: 14721 | L15: =J15+K15 -> 38879 | M15: 0 | N15: 0 | O15: 0 | P15: 0 | Q15: 0 | R15: 0 | S15: =M15+O15+Q15 -> 0 | T15: =N15+P15+R15 -> 0
A16: 12 | B16: Gujarat | C16: 1442 | D16: 486 | E16: =C16+D16 -> 1928 | F16: 330 | G16: =E16+F16 -> 2258 | H16: 496075 | I16: 476509 | J16: =H16+I16 -> 972584 | K16: 218935 | L16: =J16+K16 -> 1191519 | M16: 36 | N16: 3305 | O16: 8 | P16: 277 | Q16: 3 | R16: 203 | S16: =M16+O16+Q16 -> 47 | T16: =N16+P16+R16 -> 3785
... A22: 18 | B22: Kerala | C22: 840 | D22: 211 | E22: =C22+D22 -> 1051 | F22: 262 | G22: =E22+F22 -> 1313 | H22: 358292 | I22: 266320 | J22: =H22+I22 -> 624612 | K22: 130012 | L22: =J22+K22 -> 754624 | M22: 3 | N22: 160 | O22: 0 | P22: 0 | Q22: 0 | R22: 0 | S22: =M22+O22+Q22 -> 3 | T22: =N22+P22+R22 -> 160
A23: 19 | B23: Ladakh | C23: 0 | D23: 0 | F23: 5 | G23: =E23+F23 -> 5 | H23: 0 | I23: 0 | K23: 2398 | L23: =J23+K23 -> 2398 | M23: 0 | N23: 0 | O23: 0 | P23: 0 | Q23: 0 | R23: 0
A24: 20 | B24: Lakshadweep | C24: 0 | D24: 0 | E24: =C24+D24 -> 0 | F24: 0 | G24: =E24+F24 -> 0 | H24: 0 | I24: 0 | J24: =H24+I24 -> 0 | K24: 0 | L24: =J24+K24 -> 0 | M24: 0 | N24: 0 | O24: 0 | P24: 0 | Q24: 0 | R24: 0 | S24: =M24+O24+Q24 -> 0 | T24: =N24+P24+R24 -> 0
A25: 21 | B25: Madhya Pradesh | C25: 1128 | D25: 198 | E25: =C25+D25 -> 1326 | F25: 620 | G25: =E25+F25 -> 1946 | H25: 511707 | I25: 122673 | J25: =H25+I25 -> 634380 | K25: 866856 | L25: =J25+K25 -> 1501236 | M25: 27 | N25: 2717 | O25: 0 | P25: 0 | Q25: 3 | R25: 521 | S25: =M25+O25+Q25 -> 30 | T25: =N25+P25+R25 -> 3238
A26: 22 | B26: Maharashtra | C26: 2801 | D26: 1158 | E26: =C26+D26 -> 3959 | F26: 535 | G26: =E26+F26 -> 4494 | H26: 1219087 | I26: 1534501 | J26: =H26+I26 -> 2753588 | K26: 255831 | L26: =J26+K26 -> 3009419 | M26: 143 | N26: 13250 | O26: 5 | P26: 306 | Q26: 11 | R26: 880 | S26: =M26+O26+Q26 -> 159 | T26: =N26+P26+R26 -> 14436
A27: 23 | B27: Manipur | C27: 29 | D27: 12 | E27: =C27+D27 -> 41 | F27: 60 | G27: =E27+F27 -> 101 | H27: 8719 | I27: 19515 | J27: =H27+I27 -> 28234 | K27: 78464 | L27: =J27+K27 -> 106698 | M27: 3 | N27: 98 | O27: 1 | P27: 135 | Q27: 1 | R27: 7 | S27: =M27+O27+Q27 -> 5 | T27: =N27+P27+R27 -> 240
A28: 24 | B28: Meghalaya | C28: 16 | D28: 15 | E28: =C28+D28 -> 31 | F28: 26 | G28: =E28+F28 -> 57 | H28: 9440 | I28: 18539 | J28: =H28+I28 -> 27979 | K28: 35028 | L28: =J28+K28 -> 63007 | M28: 0 | N28: 0 | O28: 0 | P28: 0 | Q28: 0 | R28: 0 | S28: =M28+O28+Q28 -> 0 | T28: =N28+P28+R28 -> 0
A29: 25 | B29: Mizoram | C29: 3 | D29: 1 | E29: =C29+D29 -> 4 | F29: 31 | G29: =E29+F29 -> 35 | H29: 446 | I29: 37 | J29: =H29+I29 -> 483 | K29: 19097 | L29: =J29+K29 -> 19580 | M29: 0 | N29: 0 | O29: 0 | P29: 0 | Q29: 0 | R29: 0 | S29: =M29+O29+Q29 -> 0 | T29: =N29+P29+R29 -> 0
A30: 26 | B30: Nagaland | C30: 12 | D30: 34 | E30: =C30+D30 -> 46 | F30: 20 | G30: =E30+F30 -> 66 | H30: 3001 | I30: 19348 | J30: =H30+I30 -> 22349 | K30: 11115 | L30: =J30+K30 -> 33464 | M30: 0 | N30: 0 | O30: 0 | P30: 0 | Q30: 0 | R30: 0 | S30: =M30+O30+Q30 -> 0 | T30: =N30+P30+R30 -> 0
A31: 27 | B31: Odisha | C31: 282 | D31: 432 | E31: =C31+D31 -> 714 | F31: 363 | G31: =E31+F31 -> 1077 | H31: 139451 | I31: 300937 | J31: =H31+I31 -> 440388 | K31: 268975 | L31: =J31+K31 -> 709363 | M31: 1 | N31: 15 | O31: 0 | P31: 0 | Q31: 0 | R31: 0 | S31: =M31+O31+Q31 -> 1 | T31: =N31+P31+R31 -> 15
A32: 28 | B32: Puducherry | C32: 43 | D32: 1 | E32: =C32+D32 -> 44 | F32: 25 | G32: =E32+F32 -> 69 | H32: 22637 | I32: 66 | J32: =H32+I32 -> 22703 | K32: 23367 | L32: =J32+K32 -> 46070 | M32: 0 | N32: 0 | O32: 0 | P32: 0 | Q32: 0 | R32: 0 | S32: =M32+O32+Q32 -> 0 | T32: =N32+P32+R32 -> 0
A33: 29 | B33: Punjab | C33: 636 | D33: 171 | E33: =C33+D33 -> 807 | F33: 199 | G33: =E33+F33 -> 1006 | H33: 206818 | I33: 158503 | J33: =H33+I33 -> 365321 | K33: 159156 | L33: =J33+K33 -> 524477 | M33: 6 | N33: 285 | O33: 0 | P33: 0 | Q33: 1 | R33: 39 | S33: =M33+O33+Q33 -> 7 | T33: =N33+P33+R33 -> 324
A34: 30 | B34: Rajasthan | C34: 2204 | D34: 229 | E34: =C34+D34 -> 2433 | F34: 668 | G34: =E34+F34 -> 3101 | H34: 845714 | I34: 84052 | J34: =H34+I34 -> 929766 | K34: 674165 | L34: =J34+K34 -> 1603931 | M34: 61 | N34: 3780 | O34: 10 | P34: 530 | Q34: 45 | R34: 9222 | S34: =M34+O34+Q34 -> 116 | T34: =N34+P34+R34 -> 13532
A35: 31 | B35: Sikkim | C35: 5 | D35: 0 | E35: =C35+D35 -> 5 | F35: 14 | G35: =E35+F35 -> 19 | H35: 1216 | I35: 0 | J35: =H35+I35 -> 1216 | K35: 10828 | L35: =J35+K35 -> 12044 | M35: 0 | N35: 0 | O35: 0 | P35: 0 | Q35: 0 | R35: 0 | S35: =M35+O35+Q35 -> 0 | T35: =N35+P35+R35 -> 0
... A41: 37 | B41: West Bengal | C41: 682 | D41: 231 | E41: =C41+D41 -> 913 | F41: 496 | G41: =E41+F41 -> 1409 | H41: 277972 | I41: 362692 | J41: =H41+I41 -> 640664 | K41: 1021064 | L41: =J41+K41 -> 1661728 | M41: 9 | N41: 1088 | O41: 1 | P41: 50 | Q41: 2 | R41: 200 | S41: =M41+O41+Q41 -> 12 | T41: =N41+P41+R41 -> 1338
A42: All India | C42: =SUM(C5:C41) -> 26054 | D42: =SUM(D5:D41) -> 5336 | E42: =SUM(E5:E41) -> 31390 | F42: =SUM(F5:F41) -> 8565 | G42: =SUM(G5:G41) -> 39955 | H42: =SUM(H5:H41) -> 12199079 | I42: =SUM(I5:I41) -> 5817325 | J42: =SUM(J5:J41) -> 18016404 | ... T42: =SUM(T5:T41) -> 68110

Sheet 6TotalEnr
B1: Table | C1: 6. State-wise Estimated Enrolment at various levels | L1: =C1 -> 6. State-wise Estimated Enrolment at various levels | U1: =L1 -> 6. State-wise Estimated Enrolment at various levels
A2: Sl. No. | B2: State/UTs | C2: Ph.D. | F2: M.Phil. | I2: Post Graduate | L2: Under Graduate | O2: PG Diploma | R2: Diploma | U2: Certificate | X2: Integrated | AA2: Grand Total
C3: Male | D3: Female | E3: Total | F3: Male | G3: Female | H3: Total | I3: Male | J3: Female | K3: Total | L3: Male | M3: Female | N3: Total | O3: Male | P3: Female | Q3: Total | R3: Male | S3: Female | T3: Total | U3: Male | V3: Female | W3: Total | X3: Male | Y3: Female | Z3: Total | AA3: Male | AB3: Female | AC3: Total
A4: 1 | B4: 2 | C4: 3 | D4: 4 | E4: 5 | F4: 6 | G4: 7 | H4: 8 | I4: 9 | J4: 10 | K4: 11 | L4: 12 | M4: 13 | N4: 14 | O4: 15 | P4: 16 | Q4: 17 | R4: 18 | S4: 19 | T4: 20 | U4: 21 | V4: 22 | W4: 23 | X4: 24 | Y4: 25 | Z4: 26 | AA4: 27 | AB4: 28 | AC4: 29
A5: 1 | B5: Andaman and Nicobar Islands | C5: 5 | D5: 9 | E5: 14 | F5: 0 | G5: 0 | H5: 0 | I5: 571 | J5: 969 | K5: 1540 | L5: 3397 | M5: 4059 | N5: 7456 | O5: 58 | P5: 40 | Q5: 98 | R5: 310 | S5: 262 | T5: 572 | U5: 46 | V5: 36 | W5: 82 | X5: 145 | Y5: 224 | Z5: 369 | AA5: 4532 | AB5: 5599 | AC5: =AA5+AB5 -> 10131
A6: 2 | B6: Andhra Pradesh | C6: 3837 | D6: 2879 | E6: 6716 | F6: 175 | G6: 102 | H6: 277 | I6: 112024 | J6: 105816 | K6: 217840 | L6: 798084 | M6: 694983 | N6: 1493067 | O6: 1402 | P6: 879 | Q6: 2281 | R6: 93033 | S6: 60085 | T6: 153118 | U6: 3921 | V6: 6917 | W6: 10838 | X6: 8650 | Y6: 4362 | Z6: 13012 | AA6: 1021126 | AB6: 876023 | AC6: =AA6+AB6 -> 1897149
A7: 3 | B7: Arunachal Pradesh | C7: 597 | D7: 469 | E7: 1066 | F7: 77 | G7: 113 | H7: 190 | I7: 4960 | J7: 5880 | K7: 10840 | L7: 20418 | M7: 19017 | N7: 39435 | O7: 127 | P7: 144 | Q7: 271 | R7: 1308 | S7: 645 | T7: 1953 | U7: 299 | V7: 119 | W7: 418 | X7: 1015 | Y7: 628 | Z7: 1643 | AA7: 28801 | AB7: 27015 | AC7: =AA7+AB7 -> 55816
A8: 4 | B8: Assam | C8: 3214 | D8: 2413 | E8: 5627 | F8: 245 | G8: 371 | H8: 616 | I8: 27523 | J8: 39800 | K8: 67323 | L8: 269915 | M8: 278078 | N8: 547993 | O8: 1683 | P8: 1530 | Q8: 3213 | R8: 11139 | S8: 8078 | T8: 19217 | U8: 743 | V8: 1176 | W8: 1919 | X8: 2446 | Y8: 2247 | Z8: 4693 | AA8: 316908 | AB8: 333693 | AC8: =AA8+AB8 -> 650601
A9: 5 | B9: Bihar | C9: 1665 | D9: 1034 | E9: 2699 | F9: 55 | G9: 15 | H9: 70 | I9: 61287 | J9: 59654 | K9: 120941 | L9: 855740 | M9: 677529 | N9: 1533269 | O9: 1814 | P9: 801 | Q9: 2615 | R9: 43054 | S9: 25907 | T9: 68961 | U9: 4029 | V9: 2564 | W9: 6593 | X9: 2258 | Y9: 1026 | Z9: 3284 | AA9: 969902 | AB9: 768530 | AC9: =AA9+AB9 -> 1738432
A10: 6 | B10: Chandigarh | C10: 409 | D10: 550 | E10: 959 | F10: 140 | G10: 48 | H10: 188 | I10: 8560 | J10: 13854 | K10: 22414 | L10: 39098 | M10: 34415 | N10: 73513 | O10: 1065 | P10: 1115 | Q10: 2180 | R10: 2340 | S10: 1944 | T10: 4284 | U10: 419 | V10: 281 | W10: 700 | X10: 1139 | Y10: 1290 | Z10: 2429 | AA10: 53170 | AB10: 53497 | AC10: =AA10+AB10 -> 106667
A11: 7 | B11: Chhattisgarh | C11: 824 | D11: 691 | E11: 1515 | F11: 109 | G11: 89 | H11: 198 | I11: 30137 | J11: 40444 | K11: 70581 | L11: 187304 | M11: 228077 | N11: 415381 | O11: 13986 | P11: 14396 | Q11: 28382 | R11: 38361 | S11: 27702 | T11: 66063 | U11: 210 | V11: 335 | W11: 545 | X11: 1882 | Y11: 1848 | Z11: 3730 | AA11: 272813 | AB11: 313582 | AC11: =AA11+AB11 -> 586395
